--------------------------------------------------------------------------
A process has executed an operation involving a call to the
"fork()" system call to create a child process.  Open MPI is currently
operating in a condition that could result in memory corruption or
other system errors; your job may hang, crash, or produce silent
data corruption.  The use of fork() (or system() or other calls that
create child processes) is strongly discouraged.

The process that invoked fork was:

  Local host:          [[35284,1],0] (PID 39812)

If you are *absolutely sure* that your application will successfully
and correctly survive a call to fork(), you may disable this warning
by setting the mpi_warn_on_fork MCA parameter to 0.
--------------------------------------------------------------------------
/software/software/h5py/2.7.1-foss-2018a-Python-3.6.4/lib/python3.6/site-packages/h5py-2.7.1-py3.6-linux-x86_64.egg/h5py/__init__.py:36: FutureWarning: Conversion of the second argument of issubdtype from `float` to `np.floating` is deprecated. In future, it will be treated as `np.float64 == np.dtype(float).type`.
  from ._conv import register_converters as _register_converters
Using TensorFlow backend.
pygame 1.9.4
Hello from the pygame community. https://www.pygame.org/contribute.html
Enable GUI?: (1 == yes)
Do you want to load a model? (1 == yes)
Do you want to tweak parameters? (1 == yes)
Enter name of parameter to be tweaked:
Enter parameter value:
Tweak another parameter? (1 == yes)
Enter name of parameter to be tweaked:
Enter parameter value:
Tweak another parameter? (1 == yes)
Enter name of parameter to be tweaked:
Enter parameter value:
Tweak another parameter? (1 == yes)
Give saveModel folder a custom name? (1 == yes)
Super Path:  savedModels/ALGORITHM="CACLA"&EXP_REPLAY_ENABLED=False&NUM_COLLECTORS=32/
Path:  savedModels/ALGORITHM="CACLA"&EXP_REPLAY_ENABLED=False&NUM_COLLECTORS=32/$Mar-05_15:40:18:856810$/
Initialized folder: savedModels/ALGORITHM="CACLA"&EXP_REPLAY_ENABLED=False&NUM_COLLECTORS=32/$Mar-05_15:40:18:856810$/
Import package name: savedModels.ALGORITHM="CACLA"&EXP_REPLAY_ENABLED=False&NUM_COLLECTORS=32.$Mar-05_15:40:18:856810$

Initializing network...

*********************************************************************
Initializing collectors...
Process Process-5:
Traceback (most recent call last):
  File "/software/software/Python/3.6.4-foss-2018a/lib/python3.6/multiprocessing/process.py", line 258, in _bootstrap
    self.run()
  File "/software/software/Python/3.6.4-foss-2018a/lib/python3.6/multiprocessing/process.py", line 93, in run
    self._target(*self._args, **self._kwargs)
  File "./aigar.py", line 792, in performModelSteps
    os.sched_setaffinity(0, {(processNum-1)%(num_cores-1)+1})  # Core #1 is reserved for trainer process
OSError: [Errno 22] Invalid argument
Process Process-4:
Traceback (most recent call last):
  File "/software/software/Python/3.6.4-foss-2018a/lib/python3.6/multiprocessing/process.py", line 258, in _bootstrap
    self.run()
  File "/software/software/Python/3.6.4-foss-2018a/lib/python3.6/multiprocessing/process.py", line 93, in run
    self._target(*self._args, **self._kwargs)
  File "./aigar.py", line 792, in performModelSteps
    os.sched_setaffinity(0, {(processNum-1)%(num_cores-1)+1})  # Core #1 is reserved for trainer process
OSError: [Errno 22] Invalid argument
Process Process-6:
Traceback (most recent call last):
  File "/software/software/Python/3.6.4-foss-2018a/lib/python3.6/multiprocessing/process.py", line 258, in _bootstrap
    self.run()
  File "/software/software/Python/3.6.4-foss-2018a/lib/python3.6/multiprocessing/process.py", line 93, in run
    self._target(*self._args, **self._kwargs)
  File "./aigar.py", line 792, in performModelSteps
    os.sched_setaffinity(0, {(processNum-1)%(num_cores-1)+1})  # Core #1 is reserved for trainer process
OSError: [Errno 22] Invalid argument
Process Process-3:
Traceback (most recent call last):
  File "/software/software/Python/3.6.4-foss-2018a/lib/python3.6/multiprocessing/process.py", line 258, in _bootstrap
    self.run()
  File "/software/software/Python/3.6.4-foss-2018a/lib/python3.6/multiprocessing/process.py", line 93, in run
    self._target(*self._args, **self._kwargs)
  File "./aigar.py", line 792, in performModelSteps
    os.sched_setaffinity(0, {(processNum-1)%(num_cores-1)+1})  # Core #1 is reserved for trainer process
OSError: [Errno 22] Invalid argument
Process Process-7:
Traceback (most recent call last):
  File "/software/software/Python/3.6.4-foss-2018a/lib/python3.6/multiprocessing/process.py", line 258, in _bootstrap
    self.run()
  File "/software/software/Python/3.6.4-foss-2018a/lib/python3.6/multiprocessing/process.py", line 93, in run
    self._target(*self._args, **self._kwargs)
  File "./aigar.py", line 792, in performModelSteps
    os.sched_setaffinity(0, {(processNum-1)%(num_cores-1)+1})  # Core #1 is reserved for trainer process
OSError: [Errno 22] Invalid argument
Process Process-8:
Traceback (most recent call last):
  File "/software/software/Python/3.6.4-foss-2018a/lib/python3.6/multiprocessing/process.py", line 258, in _bootstrap
    self.run()
  File "/software/software/Python/3.6.4-foss-2018a/lib/python3.6/multiprocessing/process.py", line 93, in run
    self._target(*self._args, **self._kwargs)
  File "./aigar.py", line 792, in performModelSteps
    os.sched_setaffinity(0, {(processNum-1)%(num_cores-1)+1})  # Core #1 is reserved for trainer process
OSError: [Errno 22] Invalid argument
Process Process-9:
Traceback (most recent call last):
  File "/software/software/Python/3.6.4-foss-2018a/lib/python3.6/multiprocessing/process.py", line 258, in _bootstrap
    self.run()
  File "/software/software/Python/3.6.4-foss-2018a/lib/python3.6/multiprocessing/process.py", line 93, in run
    self._target(*self._args, **self._kwargs)
  File "./aigar.py", line 792, in performModelSteps
    os.sched_setaffinity(0, {(processNum-1)%(num_cores-1)+1})  # Core #1 is reserved for trainer process
OSError: [Errno 22] Invalid argument
Process Process-10:
Traceback (most recent call last):
  File "/software/software/Python/3.6.4-foss-2018a/lib/python3.6/multiprocessing/process.py", line 258, in _bootstrap
    self.run()
  File "/software/software/Python/3.6.4-foss-2018a/lib/python3.6/multiprocessing/process.py", line 93, in run
    self._target(*self._args, **self._kwargs)
  File "./aigar.py", line 792, in performModelSteps
    os.sched_setaffinity(0, {(processNum-1)%(num_cores-1)+1})  # Core #1 is reserved for trainer process
OSError: [Errno 22] Invalid argument
Process Process-11:
Traceback (most recent call last):
  File "/software/software/Python/3.6.4-foss-2018a/lib/python3.6/multiprocessing/process.py", line 258, in _bootstrap
    self.run()
  File "/software/software/Python/3.6.4-foss-2018a/lib/python3.6/multiprocessing/process.py", line 93, in run
    self._target(*self._args, **self._kwargs)
  File "./aigar.py", line 792, in performModelSteps
    os.sched_setaffinity(0, {(processNum-1)%(num_cores-1)+1})  # Core #1 is reserved for trainer process
OSError: [Errno 22] Invalid argument
Process Process-12:
Traceback (most recent call last):
  File "/software/software/Python/3.6.4-foss-2018a/lib/python3.6/multiprocessing/process.py", line 258, in _bootstrap
    self.run()
  File "/software/software/Python/3.6.4-foss-2018a/lib/python3.6/multiprocessing/process.py", line 93, in run
    self._target(*self._args, **self._kwargs)
  File "./aigar.py", line 792, in performModelSteps
    os.sched_setaffinity(0, {(processNum-1)%(num_cores-1)+1})  # Core #1 is reserved for trainer process
OSError: [Errno 22] Invalid argument
Process Process-13:
Traceback (most recent call last):
  File "/software/software/Python/3.6.4-foss-2018a/lib/python3.6/multiprocessing/process.py", line 258, in _bootstrap
    self.run()
  File "/software/software/Python/3.6.4-foss-2018a/lib/python3.6/multiprocessing/process.py", line 93, in run
    self._target(*self._args, **self._kwargs)
  File "./aigar.py", line 792, in performModelSteps
    os.sched_setaffinity(0, {(processNum-1)%(num_cores-1)+1})  # Core #1 is reserved for trainer process
OSError: [Errno 22] Invalid argument
Process Process-14:
Traceback (most recent call last):
  File "/software/software/Python/3.6.4-foss-2018a/lib/python3.6/multiprocessing/process.py", line 258, in _bootstrap
    self.run()
  File "/software/software/Python/3.6.4-foss-2018a/lib/python3.6/multiprocessing/process.py", line 93, in run
    self._target(*self._args, **self._kwargs)
  File "./aigar.py", line 792, in performModelSteps
    os.sched_setaffinity(0, {(processNum-1)%(num_cores-1)+1})  # Core #1 is reserved for trainer process
OSError: [Errno 22] Invalid argument
Process Process-15:
Traceback (most recent call last):
  File "/software/software/Python/3.6.4-foss-2018a/lib/python3.6/multiprocessing/process.py", line 258, in _bootstrap
    self.run()
  File "/software/software/Python/3.6.4-foss-2018a/lib/python3.6/multiprocessing/process.py", line 93, in run
    self._target(*self._args, **self._kwargs)
  File "./aigar.py", line 792, in performModelSteps
    os.sched_setaffinity(0, {(processNum-1)%(num_cores-1)+1})  # Core #1 is reserved for trainer process
OSError: [Errno 22] Invalid argument
Process Process-16:
Traceback (most recent call last):
  File "/software/software/Python/3.6.4-foss-2018a/lib/python3.6/multiprocessing/process.py", line 258, in _bootstrap
    self.run()
  File "/software/software/Python/3.6.4-foss-2018a/lib/python3.6/multiprocessing/process.py", line 93, in run
    self._target(*self._args, **self._kwargs)
  File "./aigar.py", line 792, in performModelSteps
    os.sched_setaffinity(0, {(processNum-1)%(num_cores-1)+1})  # Core #1 is reserved for trainer process
OSError: [Errno 22] Invalid argument
Process Process-17:
Traceback (most recent call last):
  File "/software/software/Python/3.6.4-foss-2018a/lib/python3.6/multiprocessing/process.py", line 258, in _bootstrap
    self.run()
  File "/software/software/Python/3.6.4-foss-2018a/lib/python3.6/multiprocessing/process.py", line 93, in run
    self._target(*self._args, **self._kwargs)
  File "./aigar.py", line 792, in performModelSteps
    os.sched_setaffinity(0, {(processNum-1)%(num_cores-1)+1})  # Core #1 is reserved for trainer process
OSError: [Errno 22] Invalid argument
Process Process-18:
Traceback (most recent call last):
  File "/software/software/Python/3.6.4-foss-2018a/lib/python3.6/multiprocessing/process.py", line 258, in _bootstrap
    self.run()
  File "/software/software/Python/3.6.4-foss-2018a/lib/python3.6/multiprocessing/process.py", line 93, in run
    self._target(*self._args, **self._kwargs)
  File "./aigar.py", line 792, in performModelSteps
    os.sched_setaffinity(0, {(processNum-1)%(num_cores-1)+1})  # Core #1 is reserved for trainer process
OSError: [Errno 22] Invalid argument
Process Process-19:
Traceback (most recent call last):
  File "/software/software/Python/3.6.4-foss-2018a/lib/python3.6/multiprocessing/process.py", line 258, in _bootstrap
    self.run()
  File "/software/software/Python/3.6.4-foss-2018a/lib/python3.6/multiprocessing/process.py", line 93, in run
    self._target(*self._args, **self._kwargs)
  File "./aigar.py", line 792, in performModelSteps
    os.sched_setaffinity(0, {(processNum-1)%(num_cores-1)+1})  # Core #1 is reserved for trainer process
OSError: [Errno 22] Invalid argument
Process Process-20:
Traceback (most recent call last):
  File "/software/software/Python/3.6.4-foss-2018a/lib/python3.6/multiprocessing/process.py", line 258, in _bootstrap
    self.run()
  File "/software/software/Python/3.6.4-foss-2018a/lib/python3.6/multiprocessing/process.py", line 93, in run
    self._target(*self._args, **self._kwargs)
  File "./aigar.py", line 792, in performModelSteps
    os.sched_setaffinity(0, {(processNum-1)%(num_cores-1)+1})  # Core #1 is reserved for trainer process
OSError: [Errno 22] Invalid argument
Process Process-21:
Traceback (most recent call last):
  File "/software/software/Python/3.6.4-foss-2018a/lib/python3.6/multiprocessing/process.py", line 258, in _bootstrap
    self.run()
  File "/software/software/Python/3.6.4-foss-2018a/lib/python3.6/multiprocessing/process.py", line 93, in run
    self._target(*self._args, **self._kwargs)
  File "./aigar.py", line 792, in performModelSteps
    os.sched_setaffinity(0, {(processNum-1)%(num_cores-1)+1})  # Core #1 is reserved for trainer process
OSError: [Errno 22] Invalid argument
Process Process-22:
Traceback (most recent call last):
  File "/software/software/Python/3.6.4-foss-2018a/lib/python3.6/multiprocessing/process.py", line 258, in _bootstrap
    self.run()
  File "/software/software/Python/3.6.4-foss-2018a/lib/python3.6/multiprocessing/process.py", line 93, in run
    self._target(*self._args, **self._kwargs)
  File "./aigar.py", line 792, in performModelSteps
    os.sched_setaffinity(0, {(processNum-1)%(num_cores-1)+1})  # Core #1 is reserved for trainer process
OSError: [Errno 22] Invalid argument
Process Process-24:
Traceback (most recent call last):
  File "/software/software/Python/3.6.4-foss-2018a/lib/python3.6/multiprocessing/process.py", line 258, in _bootstrap
    self.run()
  File "/software/software/Python/3.6.4-foss-2018a/lib/python3.6/multiprocessing/process.py", line 93, in run
    self._target(*self._args, **self._kwargs)
  File "./aigar.py", line 792, in performModelSteps
    os.sched_setaffinity(0, {(processNum-1)%(num_cores-1)+1})  # Core #1 is reserved for trainer process
OSError: [Errno 22] Invalid argument
Process Process-25:
Traceback (most recent call last):
  File "/software/software/Python/3.6.4-foss-2018a/lib/python3.6/multiprocessing/process.py", line 258, in _bootstrap
    self.run()
  File "/software/software/Python/3.6.4-foss-2018a/lib/python3.6/multiprocessing/process.py", line 93, in run
    self._target(*self._args, **self._kwargs)
  File "./aigar.py", line 792, in performModelSteps
    os.sched_setaffinity(0, {(processNum-1)%(num_cores-1)+1})  # Core #1 is reserved for trainer process
OSError: [Errno 22] Invalid argument
Process Process-26:
Traceback (most recent call last):
  File "/software/software/Python/3.6.4-foss-2018a/lib/python3.6/multiprocessing/process.py", line 258, in _bootstrap
    self.run()
  File "/software/software/Python/3.6.4-foss-2018a/lib/python3.6/multiprocessing/process.py", line 93, in run
    self._target(*self._args, **self._kwargs)
  File "./aigar.py", line 792, in performModelSteps
    os.sched_setaffinity(0, {(processNum-1)%(num_cores-1)+1})  # Core #1 is reserved for trainer process
OSError: [Errno 22] Invalid argument
Process Process-28:
Traceback (most recent call last):
  File "/software/software/Python/3.6.4-foss-2018a/lib/python3.6/multiprocessing/process.py", line 258, in _bootstrap
    self.run()
  File "/software/software/Python/3.6.4-foss-2018a/lib/python3.6/multiprocessing/process.py", line 93, in run
    self._target(*self._args, **self._kwargs)
  File "./aigar.py", line 792, in performModelSteps
    os.sched_setaffinity(0, {(processNum-1)%(num_cores-1)+1})  # Core #1 is reserved for trainer process
OSError: [Errno 22] Invalid argument
Process Process-27:
Traceback (most recent call last):
  File "/software/software/Python/3.6.4-foss-2018a/lib/python3.6/multiprocessing/process.py", line 258, in _bootstrap
    self.run()
  File "/software/software/Python/3.6.4-foss-2018a/lib/python3.6/multiprocessing/process.py", line 93, in run
    self._target(*self._args, **self._kwargs)
  File "./aigar.py", line 792, in performModelSteps
    os.sched_setaffinity(0, {(processNum-1)%(num_cores-1)+1})  # Core #1 is reserved for trainer process
OSError: [Errno 22] Invalid argument
Process Process-29:
Traceback (most recent call last):
  File "/software/software/Python/3.6.4-foss-2018a/lib/python3.6/multiprocessing/process.py", line 258, in _bootstrap
    self.run()
  File "/software/software/Python/3.6.4-foss-2018a/lib/python3.6/multiprocessing/process.py", line 93, in run
    self._target(*self._args, **self._kwargs)
  File "./aigar.py", line 792, in performModelSteps
    os.sched_setaffinity(0, {(processNum-1)%(num_cores-1)+1})  # Core #1 is reserved for trainer process
OSError: [Errno 22] Invalid argument
Process Process-30:
Traceback (most recent call last):
  File "/software/software/Python/3.6.4-foss-2018a/lib/python3.6/multiprocessing/process.py", line 258, in _bootstrap
    self.run()
  File "/software/software/Python/3.6.4-foss-2018a/lib/python3.6/multiprocessing/process.py", line 93, in run
    self._target(*self._args, **self._kwargs)
  File "./aigar.py", line 792, in performModelSteps
    os.sched_setaffinity(0, {(processNum-1)%(num_cores-1)+1})  # Core #1 is reserved for trainer process
OSError: [Errno 22] Invalid argument
Process Process-31:
Traceback (most recent call last):
  File "/software/software/Python/3.6.4-foss-2018a/lib/python3.6/multiprocessing/process.py", line 258, in _bootstrap
    self.run()
  File "/software/software/Python/3.6.4-foss-2018a/lib/python3.6/multiprocessing/process.py", line 93, in run
    self._target(*self._args, **self._kwargs)
  File "./aigar.py", line 792, in performModelSteps
    os.sched_setaffinity(0, {(processNum-1)%(num_cores-1)+1})  # Core #1 is reserved for trainer process
OSError: [Errno 22] Invalid argument
Process Process-32:
Traceback (most recent call last):
  File "/software/software/Python/3.6.4-foss-2018a/lib/python3.6/multiprocessing/process.py", line 258, in _bootstrap
    self.run()
  File "/software/software/Python/3.6.4-foss-2018a/lib/python3.6/multiprocessing/process.py", line 93, in run
    self._target(*self._args, **self._kwargs)
  File "./aigar.py", line 792, in performModelSteps
    os.sched_setaffinity(0, {(processNum-1)%(num_cores-1)+1})  # Core #1 is reserved for trainer process
OSError: [Errno 22] Invalid argument
Process Process-33:
Traceback (most recent call last):
  File "/software/software/Python/3.6.4-foss-2018a/lib/python3.6/multiprocessing/process.py", line 258, in _bootstrap
    self.run()
  File "/software/software/Python/3.6.4-foss-2018a/lib/python3.6/multiprocessing/process.py", line 93, in run
    self._target(*self._args, **self._kwargs)
  File "./aigar.py", line 792, in performModelSteps
    os.sched_setaffinity(0, {(processNum-1)%(num_cores-1)+1})  # Core #1 is reserved for trainer process
OSError: [Errno 22] Invalid argument
Process Process-34:
Traceback (most recent call last):
  File "/software/software/Python/3.6.4-foss-2018a/lib/python3.6/multiprocessing/process.py", line 258, in _bootstrap
    self.run()
  File "/software/software/Python/3.6.4-foss-2018a/lib/python3.6/multiprocessing/process.py", line 93, in run
    self._target(*self._args, **self._kwargs)
  File "./aigar.py", line 792, in performModelSteps
    os.sched_setaffinity(0, {(processNum-1)%(num_cores-1)+1})  # Core #1 is reserved for trainer process
OSError: [Errno 22] Invalid argument
slurmstepd: error: *** JOB 4561548 ON pg-node045 CANCELLED AT 2019-03-06T14:38:39 DUE TO TIME LIMIT ***


###############################################################################
Peregrine Cluster
Job 4561548 for user 'f115844'
Finished at: Wed Mar  6 14:38:41 CET 2019

Job details:
============

Name                : ALGORITHM-`CACLA`_EXP_REPLAY_ENABLED-False_NUM_COLLECTORS-32.sh
User                : f115844
Partition           : regular
Nodes               : pg-node045
Cores               : 1
State               : CANCELLED,TIMEOUT
Submit              : 2019-03-05T15:38:22
Start               : 2019-03-05T15:38:22
End                 : 2019-03-06T14:38:40
Reserved walltime   : 23:00:00
Used walltime       : 23:00:18
Used CPU time       : 00:44:39 (efficiency:  3.24%)
% User (Computation): 83.49%
% System (I/O)      : 16.51%
Mem reserved        : 20000M/node
Max Mem used        : 236.96M (pg-node045)
Max Disk Write      : 81.92K (pg-node045)
Max Disk Read       : 2.66M (pg-node045)


Acknowledgements:
=================

Please see this page if you want to acknowledge Peregrine in your publications:

https://redmine.hpc.rug.nl/redmine/projects/peregrine/wiki/ScientificOutput

################################################################################
